# 错误处理

## 1.Error

1. `js`有一个`Error`类，用于处理异常

```ts
try {
    throw new Error("Something bad happened");
} catch (e) {
    console.log(e);
}
```

2. 错误对象显示 3 个属性

-   `name`: 错误的类型。
-   `message`: 包含错误消息的字符串。
-   `stack`: 函数执行的堆栈跟踪。

3. 额外的内置错误子类型，继承自`Error`类
4. 不需要 `throw` 抛出一个错误, 使用 `Error` 对象的基本好处是，它能自动跟踪堆栈的属性构建以及生成位置

## 2.Error 类型

1. `RangeError`
    - 当数字类型变量或者参数超出其有效范围时，出现 `RangeError` 的错误提示
    ```ts
    // 使用过多参数调用 console
    // RangeError: 数组长度无效
    console.log.apply(console, new Array(1000000000));
    // Uncaught RangeError: Maximum call stack size exceeded
    function loop(i) {
        loop(i+1);
    }
    loop(1);
    ```
2. `ReferenceError`
    - 当引用无效时，会出现 `ReferenceError` 的错误提示
    ```ts
    "use strict";
    console.log(notValidVar); // ReferenceError: notValidVar 未定义
    ```
3. `SyntaxError`
    - 当解析无效 `JavaScript` 代码时，会出现 `SyntaxError` 的错误提示
    ```ts
    1 *** 3 // SyntaxError: 无效的标记 *
    let age b = 18; // Uncaught SyntaxError: Unexpected identifier 'b'
    ```
4. `TypeError`
    - 变量或者参数不是有效类型时，会出现 TypeError 的错误提示
    ```ts
    "1.2".toPrecision(1); // TypeError: '1.2'.toPrecision 不是函数。
    ```
5. `URIError`
    - 当传入无效参数至 `encodeURI()` 和 `decodeURI()` 时，会出现 `URIError` 的错误提示
    ```ts
    decodeURI("%"); // URIError: URL 异常
    ```
6. `EvalError`

    - 当`eval`使用不当时便会抛出`EvalError`
    - `ECMAScript` 规范不再抛出此错误

    ```ts
    try {
        throw new EvalError("EvalError has occurred");
    } catch (e) {
        console.log(e instanceof EvalError); // true
        console.log(e.message); // EvalError has occurred
        console.log(e.name); // EvalError
    }
    ```

7. `InternalError`
    - `InternalError` 对象表示出现在`JavaScript` 引擎内部的错误。 
    - 例如：` "InternalError: too much recursion"`（内部错误：递归过深）。
    - "too many switch cases"（过多case子句）；
    - "too many parentheses in regular expression"（正则表达式中括号过多）；
    - "array initializer too large"（数组初始化器过大）；
    - "too much recursion"（递归过深）。
    - `ECMAScript` 规范不再抛出此错误
8. `DOMException`
    - 浏览器违规操作 dom
    ```ts
    // Uncaught DOMException: Node.appendChild: May not add a Document as a child
    document.body.appendChild(document.cloneNode(true));
    ```

## 3.try catch 处理同步错误

```js
try {
    console.log("step1");
    throw EvalError("2222");
} catch (error) {
    console.log("step2");
} finally {
    console.log("step3");
}
```

## 4.迭代器错误处理

```js
function* generate() {
    yield 33;
    yield 99;
}
const go = generate();
const firstStep = go.next().value; // 33
go.throw(Error("Tired of iterating!"));
const secondStep = go.next().value; // never reached
```

```js
async function* asyncGenerator() {
    yield 33;
    yield 99;
    throw Error("Something went wrong!"); // Promise.reject
}

const go = asyncGenerator();
go.next().then((value) => console.log(value));
go.next().then((value) => console.log(value));
go.next().catch((reason) => console.error(reason.message)); // Something went wrong!
```

```js
async function* asyncGenerator() {
    yield 33;
    yield 99;
    throw Error("Something went wrong!"); // Promise.reject
}
async function consumer() {
    for await (const value of asyncGenerator()) {
        // 33
        // 99
        // Uncaught (in promise) Error: Something went wrong!
        console.log(value);
    }
}
consumer();
```

## 5.DOM 事件的错误处理机制遵循异步 WebAPI 的模式

1. 传递给`addEventListener` 的任何回调均 异步 执行

## 6.onerror

1. 每当`<img>`标签或`<script>`之类的 `HTML` 元素遇到不存在的资源时，`onerror` 事件处理器都会触发。

```js
const image = document.querySelector("img");
image.onerror = function (event) {
    console.log(event);
};
```

```js
const image = document.querySelector("img");
image.addEventListener("error", function (event) {
    console.log(event);
});
```

## 7.Promise 错误处理

1. 使用`Promise.reject`错误处理

```js
function toUppercase(string) {
    if (typeof string !== "string") {
        return Promise.reject(TypeError("Wrong type given, expected a string"));
    }
    const result = string.toUpperCase();
    return Promise.resolve(result);
}

toUppercase(99)
    .then((result) => result)
    .catch((error) => console.error(error.message));
```

2. 使用`throw`错误处理

```js
Promise.resolve("A string")
    .then((value) => {
        if (typeof value === "string") {
            throw TypeError("Expected a number!");
        }
    })
    .catch((reason) => console.log(reason.message));
```

2. `Promise.all`错误处理

```js
const promise1 = Promise.resolve("All good!");
const promise2 = Promise.reject(Error("No good, sorry!"));
const promise3 = Promise.reject(Error("Bad day ..."));
Promise.all([promise1, promise2, promise3])
    .then((results) => console.log(results))
    .catch((error) => console.error(error.message)); // No good, sorry!
```

3. `Promise.any`错误处理

```js
const promise1 = Promise.reject(Error("No good, sorry!"));
const promise2 = Promise.reject(Error("Bad day ..."));
Promise.any([promise1, promise2])
    .then((result) => console.log(result))
    .catch((error) => console.error(error)) // AggregateError: All promises were rejected
    .finally(() => console.log("Always runs!"));
```

4. `Promise.race`错误处理

```js
const promise1 = Promise.resolve("The first!");
const rejection = Promise.reject(Error("Ouch!"));
const promise2 = Promise.resolve("The second!");
Promise.race([rejection, promise1, promise2])
    .then((result) => console.log(result))
    .catch((error) => console.error(error.message)); // Ouch!
```

5. `Promise.allSettled`错误处理

```js
const promise1 = Promise.reject("Good!");
const promise2 = Promise.reject(Error("No good, sorry!"));
Promise.allSettled([promise1, promise2])
    .then((results) => console.log(JSON.stringify(results))) // [{"status":"rejected","reason":"Good!"},{"status":"rejected","reason":{}}]
    .catch((error) => console.error(error)) // 永远不会执行
    .finally(() => console.log("Always runs!"));
```

## 8.Node.js 错误处理

1. 回调模式

```js
const { readFile } = require("fs");
function readDataset(path) {
    readFile(path, { encoding: "utf8" }, function (error, data) {
        if (error) return errorHandler(error);
        // do stuff with the data
    });
}

function errorHandler(error) {
    console.error(error.message);
    // do something with the error:
    // - write to a log.
    // - send to an external logger.
}
```

2. 事件模式

```js
const net = require("net");
const server1 = net.createServer().listen(80, "127.0.0.1");
server1.on("listening", function () {
    console.log("Server listening!");
});

const server2 = net.createServer().listen(80, "127.0.0.1");
server2.on("listening", function () {
    console.log("Server listening!");
});

server2.on("error", function (error) {
    console.error("1111", error.message); // 1111 listen EADDRINUSE: address already in use 127.0.0.1:80
});
```
